Workbook

Sheet Calculator
A1: Generator fuel calculator (engine-family model v3)
A2: Yellow cells are inputs. Fuel per hour = country × rated kW × (a + b×loading + q×loading²). L/kWh = fuel per hour ÷ (rated kW × loading).
A4: Engine family | B4: Cummins KTA50 (1250 kVA)
A5: Country | B5: UAE
A6: Rated kVA | B6: 500
A7: Loading (fraction of rated kW) | B7: 0.35
A8: Family options: Cummins KTA50 (1250 kVA), Cummins QSG12 (350 kVA), Cummins QSK23 (800 kVA), Cummins QSL9 (250–300 kVA), Cummins QST30 (1000 kVA), Cummins QSX15 (500 kVA), JCB 448 (125 kVA), JCB 448 (60 kVA), JD 6068 (220 kVA), JD 6090 (300 kVA), Scania DC13 (500 kVA), Volvo TAD1651 (500 kVA), unlisted 200–220 kVA, unlisted 300 kVA, unlisted 500 kVA, unlisted ≤125 kVA
A10: a (fixed, L per rated-kW-hour) | B10: =INDEX(Coefficients!$C$2:$C$40,MATCH($B$4,Coefficients!$A$2:$A$40,0)) -> 0.040546959
A11: b (marginal, L/kWh) | B11: =INDEX(Coefficients!$D$2:$D$40,MATCH($B$4,Coefficients!$A$2:$A$40,0)) -> 0.1797637
A12: q (quadratic, L/kWh per unit loading) | B12: =Coefficients!$H$2 -> 0.078693631
A13: Country multiplier | B13: =IF($B$5="KSA",Coefficients!$H$3,Coefficients!$H$4) -> 0.97128494
A14: Rated kW (kVA × 0.8) | B14: =B6*0.8 -> 400
A15: Fuel at this loading, L/h | B15: =B13*B14*(B10+B11*B7+B12*B7^2) -> 43.942573
A16: L/kWh at this loading | B16: =B15/(B14*B7) -> 0.31387552
A17: L/kWh at 25% / 50% / 75% | B17: =B13*(B11+B10/0.25+B12*0.25) -> 0.35124087 | C17: =B13*(B11+B10/0.5+B12*0.5) -> 0.29158405 | D17: =B13*(B11+B10/0.75+B12*0.75) -> 0.28443743

Sheet Coefficients
A1: Engine family | B1: Rated kVA (typical) | C1: a fixed (L per rated-kW-h) | D1: b marginal (L/kWh) | E1: site-months in fit | F1: sites in fit | G1: Share of fleet kWh | H1: q, KSA, UAE
A2: Cummins KTA50 (1250 kVA) | B2: 1250 | C2: 0.040546959 | D2: 0.1797637 | E2: 66 | F2: 8 | G2: 0.3255 | H2: 0.078693631 | I2: q (quadratic)
A3: Cummins QSG12 (350 kVA) | B3: 350 | C3: 0.041424575 | D3: 0.18515627 | E3: 45 | F3: 8 | G3: 0.0198 | H3: 1.0537962 | I3: KSA multiplier
A4: Cummins QSK23 (800 kVA) | B4: 800 | C4: 0.031930149 | D4: 0.18469495 | E4: 75 | F4: 7 | G4: 0.1606 | H4: 0.97128494 | I4: UAE multiplier
A5: Cummins QSL9 (250–300 kVA) | B5: 300 | C5: 0.040356984 | D5: 0.19691019 | E5: 48 | F5: 7 | G5: 0.0161
A6: Cummins QST30 (1000 kVA) | B6: 1000 | C6: 0.018754456 | D6: 0.2077759 | E6: 69 | F6: 7 | G6: 0.1163
A7: Cummins QSX15 (500 kVA) | B7: 500 | C7: 0.037420223 | D7: 0.18977029 | E7: 44 | F7: 6 | G7: 0.0455
A8: JCB 448 (125 kVA) | B8: 125 | C8: 0.039876841 | D8: 0.2335885 | E8: 97 | F8: 10 | G8: 0.0177
A9: JCB 448 (60 kVA) | B9: 60 | C9: 0.0079596911 | D9: 0.27159789 | E9: 15 | F9: 2 | G9: 0.0008
A10: JD 6068 (220 kVA) | B10: 220 | C10: 0.047305739 | D10: 0.25525516 | E10: 78 | F10: 9 | G10: 0.0125
A11: JD 6090 (300 kVA) | B11: 300 | C11: 0.042325181 | D11: 0.28671392 | E11: 101 | F11: 16 | G11: 0.0112
A12: Scania DC13 (500 kVA) | B12: 500 | C12: 0.025915443 | D12: 0.1683476 | E12: 8 | F12: 1 | G12: 0.0381
A13: Volvo TAD1651 (500 kVA) | B13: 500 | C13: 0.033438689 | D13: 0.19946637 | E13: 143 | F13: 18 | G13: 0.1675
A14: unlisted 200–220 kVA | B14: 220 | C14: 0 | D14: 0.41547779 | E14: 9 | F14: 3 | G14: 0.0022
A15: unlisted 300 kVA | B15: 300 | C15: 0.052485385 | D15: 0.11620425 | E15: 11 | F15: 2 | G15: 0.0064
A16: unlisted 500 kVA | B16: 500 | C16: 0.045588811 | D16: 0.14429017 | E16: 34 | F16: 5 | G16: 0.0498
A17: unlisted ≤125 kVA | B17: 125 | C17: 0.027284278 | D17: 0.28785902 | E17: 17 | F17: 1 | G17: 0.0032
A25: Fitted on 384 site-months (Jan 2025–Sep 2026) from 37 sites: monthly-report fuel vs hourly unit counters, leave-one-site-out tested. Families from the RSS generator list (Oct 2026). "unlisted" = units with no make/model in the list.

Sheet Curves L per kWh
A1: Engine family | B1: Country | C1: 25% | D1: 35% | E1: 50% | F1: 75% | G1: 35% low (p10) | H1: 35% high (p90)
A2: Cummins KTA50 (1250 kVA) | B2: KSA | C2: =Coefficients!$H$3*(INDEX(Coefficients!$D$2:$D$40,MATCH($A2,Coefficients!$A$2:$A$40,0))+INDEX(Coefficients!$C$2:$C$40,MATCH($A2,Coefficients!$A$2:$A$40,0))/0.25+Coefficients!$H$2*0.25) -> 0.38107898 | D2: =Coefficients!$H$3*(INDEX(Coefficients!$D$2:$D$40,MATCH($A2,Coefficients!$A$2:$A$40,0))+INDEX(Coefficients!$C$2:$C$40,MATCH($A2,Coefficients!$A$2:$A$40,0))/0.35+Coefficients!$H$2*0.35) -> 0.34053943 | E2: =Coefficients!$H$3*(INDEX(Coefficients!$D$2:$D$40,MATCH($A2,Coefficients!$A$2:$A$40,0))+INDEX(Coefficients!$C$2:$C$40,MATCH($A2,Coefficients!$A$2:$A$40,0))/0.5+Coefficients!$H$2*0.5) -> 0.31635429 | F2: =Coefficients!$H$3*(INDEX(Coefficients!$D$2:$D$40,MATCH($A2,Coefficients!$A$2:$A$40,0))+INDEX(Coefficients!$C$2:$C$40,MATCH($A2,Coefficients!$A$2:$A$40,0))/0.75+Coefficients!$H$2*0.75) -> 0.30860056 | G2: 0.329 | H2: 0.351
A3: Cummins KTA50 (1250 kVA) | B3: UAE | C3: =Coefficients!$H$4*(INDEX(Coefficients!$D$2:$D$40,MATCH($A3,Coefficients!$A$2:$A$40,0))+INDEX(Coefficients!$C$2:$C$40,MATCH($A3,Coefficients!$A$2:$A$40,0))/0.25+Coefficients!$H$2*0.25) -> 0.35124087 | D3: =Coefficients!$H$4*(INDEX(Coefficients!$D$2:$D$40,MATCH($A3,Coefficients!$A$2:$A$40,0))+INDEX(Coefficients!$C$2:$C$40,MATCH($A3,Coefficients!$A$2:$A$40,0))/0.35+Coefficients!$H$2*0.35) -> 0.31387552 | E3: =Coefficients!$H$4*(INDEX(Coefficients!$D$2:$D$40,MATCH($A3,Coefficients!$A$2:$A$40,0))+INDEX(Coefficients!$C$2:$C$40,MATCH($A3,Coefficients!$A$2:$A$40,0))/0.5+Coefficients!$H$2*0.5) -> 0.29158405 | F3: =Coefficients!$H$4*(INDEX(Coefficients!$D$2:$D$40,MATCH($A3,Coefficients!$A$2:$A$40,0))+INDEX(Coefficients!$C$2:$C$40,MATCH($A3,Coefficients!$A$2:$A$40,0))/0.75+Coefficients!$H$2*0.75) -> 0.28443743 | G3: 0.303 | H3: 0.337
A4: Cummins QSG12 (350 kVA) | B4: KSA | C4: =Coefficients!$H$3*(INDEX(Coefficients!$D$2:$D$40,MATCH($A4,Coefficients!$A$2:$A$40,0))+INDEX(Coefficients!$C$2:$C$40,MATCH($A4,Coefficients!$A$2:$A$40,0))/0.25+Coefficients!$H$2*0.25) -> 0.39046097 | D4: =Coefficients!$H$3*(INDEX(Coefficients!$D$2:$D$40,MATCH($A4,Coefficients!$A$2:$A$40,0))+INDEX(Coefficients!$C$2:$C$40,MATCH($A4,Coefficients!$A$2:$A$40,0))/0.35+Coefficients!$H$2*0.35) -> 0.34886446 | E4: =Coefficients!$H$3*(INDEX(Coefficients!$D$2:$D$40,MATCH($A4,Coefficients!$A$2:$A$40,0))+INDEX(Coefficients!$C$2:$C$40,MATCH($A4,Coefficients!$A$2:$A$40,0))/0.5+Coefficients!$H$2*0.5) -> 0.32388661 | F4: =Coefficients!$H$3*(INDEX(Coefficients!$D$2:$D$40,MATCH($A4,Coefficients!$A$2:$A$40,0))+INDEX(Coefficients!$C$2:$C$40,MATCH($A4,Coefficients!$A$2:$A$40,0))/0.75+Coefficients!$H$2*0.75) -> 0.31551633 | G4: 0.31 | H4: 0.392
A5: Cummins QSG12 (350 kVA) | B5: UAE | C5: =Coefficients!$H$4*(INDEX(Coefficients!$D$2:$D$40,MATCH($A5,Coefficients!$A$2:$A$40,0))+INDEX(Coefficients!$C$2:$C$40,MATCH($A5,Coefficients!$A$2:$A$40,0))/0.25+Coefficients!$H$2*0.25) -> 0.35988825 | D5: =Coefficients!$H$4*(INDEX(Coefficients!$D$2:$D$40,MATCH($A5,Coefficients!$A$2:$A$40,0))+INDEX(Coefficients!$C$2:$C$40,MATCH($A5,Coefficients!$A$2:$A$40,0))/0.35+Coefficients!$H$2*0.35) -> 0.32154871 | E5: =Coefficients!$H$4*(INDEX(Coefficients!$D$2:$D$40,MATCH($A5,Coefficients!$A$2:$A$40,0))+INDEX(Coefficients!$C$2:$C$40,MATCH($A5,Coefficients!$A$2:$A$40,0))/0.5+Coefficients!$H$2*0.5) -> 0.2985266 | F5: =Coefficients!$H$4*(INDEX(Coefficients!$D$2:$D$40,MATCH($A5,Coefficients!$A$2:$A$40,0))+INDEX(Coefficients!$C$2:$C$40,MATCH($A5,Coefficients!$A$2:$A$40,0))/0.75+Coefficients!$H$2*0.75) -> 0.29081171 | G5: 0.294 | H5: 0.364
A6: Cummins QSK23 (800 kVA) | B6: KSA | C6: =Coefficients!$H$3*(INDEX(Coefficients!$D$2:$D$40,MATCH($A6,Coefficients!$A$2:$A$40,0))+INDEX(Coefficients!$C$2:$C$40,MATCH($A6,Coefficients!$A$2:$A$40,0))/0.25+Coefficients!$H$2*0.25) -> 0.34995407 | D6: =Coefficients!$H$3*(INDEX(Coefficients!$D$2:$D$40,MATCH($A6,Coefficients!$A$2:$A$40,0))+INDEX(Coefficients!$C$2:$C$40,MATCH($A6,Coefficients!$A$2:$A$40,0))/0.35+Coefficients!$H$2*0.35) -> 0.31979207 | E6: =Coefficients!$H$3*(INDEX(Coefficients!$D$2:$D$40,MATCH($A6,Coefficients!$A$2:$A$40,0))+INDEX(Coefficients!$C$2:$C$40,MATCH($A6,Coefficients!$A$2:$A$40,0))/0.5+Coefficients!$H$2*0.5) -> 0.30339009 | F6: =Coefficients!$H$3*(INDEX(Coefficients!$D$2:$D$40,MATCH($A6,Coefficients!$A$2:$A$40,0))+INDEX(Coefficients!$C$2:$C$40,MATCH($A6,Coefficients!$A$2:$A$40,0))/0.75+Coefficients!$H$2*0.75) -> 0.30168994 | G6: 0.299 | H6: 0.326
A7: Cummins QSK23 (800 kVA) | B7: UAE | C7: =Coefficients!$H$4*(INDEX(Coefficients!$D$2:$D$40,MATCH($A7,Coefficients!$A$2:$A$40,0))+INDEX(Coefficients!$C$2:$C$40,MATCH($A7,Coefficients!$A$2:$A$40,0))/0.25+Coefficients!$H$2*0.25) -> 0.322553 | D7: =Coefficients!$H$4*(INDEX(Coefficients!$D$2:$D$40,MATCH($A7,Coefficients!$A$2:$A$40,0))+INDEX(Coefficients!$C$2:$C$40,MATCH($A7,Coefficients!$A$2:$A$40,0))/0.35+Coefficients!$H$2*0.35) -> 0.29475266 | E7: =Coefficients!$H$4*(INDEX(Coefficients!$D$2:$D$40,MATCH($A7,Coefficients!$A$2:$A$40,0))+INDEX(Coefficients!$C$2:$C$40,MATCH($A7,Coefficients!$A$2:$A$40,0))/0.5+Coefficients!$H$2*0.5) -> 0.27963494 | F7: =Coefficients!$H$4*(INDEX(Coefficients!$D$2:$D$40,MATCH($A7,Coefficients!$A$2:$A$40,0))+INDEX(Coefficients!$C$2:$C$40,MATCH($A7,Coefficients!$A$2:$A$40,0))/0.75+Coefficients!$H$2*0.75) -> 0.27806791 | G7: 0.285 | H7: 0.299
A8: Cummins QSL9 (250–300 kVA) | B8: KSA | C8: =Coefficients!$H$3*(INDEX(Coefficients!$D$2:$D$40,MATCH($A8,Coefficients!$A$2:$A$40,0))+INDEX(Coefficients!$C$2:$C$40,MATCH($A8,Coefficients!$A$2:$A$40,0))/0.25+Coefficients!$H$2*0.25) -> 0.39834711 | D8: =Coefficients!$H$3*(INDEX(Coefficients!$D$2:$D$40,MATCH($A8,Coefficients!$A$2:$A$40,0))+INDEX(Coefficients!$C$2:$C$40,MATCH($A8,Coefficients!$A$2:$A$40,0))/0.35+Coefficients!$H$2*0.35) -> 0.35803634 | E8: =Coefficients!$H$3*(INDEX(Coefficients!$D$2:$D$40,MATCH($A8,Coefficients!$A$2:$A$40,0))+INDEX(Coefficients!$C$2:$C$40,MATCH($A8,Coefficients!$A$2:$A$40,0))/0.5+Coefficients!$H$2*0.5) -> 0.3340228 | F8: =Coefficients!$H$3*(INDEX(Coefficients!$D$2:$D$40,MATCH($A8,Coefficients!$A$2:$A$40,0))+INDEX(Coefficients!$C$2:$C$40,MATCH($A8,Coefficients!$A$2:$A$40,0))/0.75+Coefficients!$H$2*0.75) -> 0.32640254 | G8: 0.34 | H8: 0.371
A9: Cummins QSL9 (250–300 kVA) | B9: UAE | C9: =Coefficients!$H$4*(INDEX(Coefficients!$D$2:$D$40,MATCH($A9,Coefficients!$A$2:$A$40,0))+INDEX(Coefficients!$C$2:$C$40,MATCH($A9,Coefficients!$A$2:$A$40,0))/0.25+Coefficients!$H$2*0.25) -> 0.36715691 | D9: =Coefficients!$H$4*(INDEX(Coefficients!$D$2:$D$40,MATCH($A9,Coefficients!$A$2:$A$40,0))+INDEX(Coefficients!$C$2:$C$40,MATCH($A9,Coefficients!$A$2:$A$40,0))/0.35+Coefficients!$H$2*0.35) -> 0.33000244 | E9: =Coefficients!$H$4*(INDEX(Coefficients!$D$2:$D$40,MATCH($A9,Coefficients!$A$2:$A$40,0))+INDEX(Coefficients!$C$2:$C$40,MATCH($A9,Coefficients!$A$2:$A$40,0))/0.5+Coefficients!$H$2*0.5) -> 0.30786914 | F9: =Coefficients!$H$4*(INDEX(Coefficients!$D$2:$D$40,MATCH($A9,Coefficients!$A$2:$A$40,0))+INDEX(Coefficients!$C$2:$C$40,MATCH($A9,Coefficients!$A$2:$A$40,0))/0.75+Coefficients!$H$2*0.75) -> 0.30084553 | G9: 0.326 | H9: 0.341
A10: Cummins QST30 (1000 kVA) | B10: KSA | C10: =Coefficients!$H$3*(INDEX(Coefficients!$D$2:$D$40,MATCH($A10,Coefficients!$A$2:$A$40,0))+INDEX(Coefficients!$C$2:$C$40,MATCH($A10,Coefficients!$A$2:$A$40,0))/0.25+Coefficients!$H$2*0.25) -> 0.3187387 | D10: =Coefficients!$H$3*(INDEX(Coefficients!$D$2:$D$40,MATCH($A10,Coefficients!$A$2:$A$40,0))+INDEX(Coefficients!$C$2:$C$40,MATCH($A10,Coefficients!$A$2:$A$40,0))/0.35+Coefficients!$H$2*0.35) -> 0.3044447 | E10: =Coefficients!$H$3*(INDEX(Coefficients!$D$2:$D$40,MATCH($A10,Coefficients!$A$2:$A$40,0))+INDEX(Coefficients!$C$2:$C$40,MATCH($A10,Coefficients!$A$2:$A$40,0))/0.5+Coefficients!$H$2*0.5) -> 0.29994372 | F10: =Coefficients!$H$3*(INDEX(Coefficients!$D$2:$D$40,MATCH($A10,Coefficients!$A$2:$A$40,0))+INDEX(Coefficients!$C$2:$C$40,MATCH($A10,Coefficients!$A$2:$A$40,0))/0.75+Coefficients!$H$2*0.75) -> 0.3074999 | G10: 0.292 | H10: 0.331
A11: Cummins QST30 (1000 kVA) | B11: UAE | C11: =Coefficients!$H$4*(INDEX(Coefficients!$D$2:$D$40,MATCH($A11,Coefficients!$A$2:$A$40,0))+INDEX(Coefficients!$C$2:$C$40,MATCH($A11,Coefficients!$A$2:$A$40,0))/0.25+Coefficients!$H$2*0.25) -> 0.29378177 | D11: =Coefficients!$H$4*(INDEX(Coefficients!$D$2:$D$40,MATCH($A11,Coefficients!$A$2:$A$40,0))+INDEX(Coefficients!$C$2:$C$40,MATCH($A11,Coefficients!$A$2:$A$40,0))/0.35+Coefficients!$H$2*0.35) -> 0.28060697 | E11: =Coefficients!$H$4*(INDEX(Coefficients!$D$2:$D$40,MATCH($A11,Coefficients!$A$2:$A$40,0))+INDEX(Coefficients!$C$2:$C$40,MATCH($A11,Coefficients!$A$2:$A$40,0))/0.5+Coefficients!$H$2*0.5) -> 0.27645842 | F11: =Coefficients!$H$4*(INDEX(Coefficients!$D$2:$D$40,MATCH($A11,Coefficients!$A$2:$A$40,0))+INDEX(Coefficients!$C$2:$C$40,MATCH($A11,Coefficients!$A$2:$A$40,0))/0.75+Coefficients!$H$2*0.75) -> 0.28342295 | G11: 0.271 | H11: 0.312
A12: Cummins QSX15 (500 kVA) | B12: KSA | C12: =Coefficients!$H$3*(INDEX(Coefficients!$D$2:$D$40,MATCH($A12,Coefficients!$A$2:$A$40,0))+INDEX(Coefficients!$C$2:$C$40,MATCH($A12,Coefficients!$A$2:$A$40,0))/0.25+Coefficients!$H$2*0.25) -> 0.37844411 | D12: =Coefficients!$H$3*(INDEX(Coefficients!$D$2:$D$40,MATCH($A12,Coefficients!$A$2:$A$40,0))+INDEX(Coefficients!$C$2:$C$40,MATCH($A12,Coefficients!$A$2:$A$40,0))/0.35+Coefficients!$H$2*0.35) -> 0.3416702 | E12: =Coefficients!$H$3*(INDEX(Coefficients!$D$2:$D$40,MATCH($A12,Coefficients!$A$2:$A$40,0))+INDEX(Coefficients!$C$2:$C$40,MATCH($A12,Coefficients!$A$2:$A$40,0))/0.5+Coefficients!$H$2*0.5) -> 0.3203093 | F12: =Coefficients!$H$3*(INDEX(Coefficients!$D$2:$D$40,MATCH($A12,Coefficients!$A$2:$A$40,0))+INDEX(Coefficients!$C$2:$C$40,MATCH($A12,Coefficients!$A$2:$A$40,0))/0.75+Coefficients!$H$2*0.75) -> 0.3147522 | G12: 0.329 | H12: 0.369
A13: Cummins QSX15 (500 kVA) | B13: UAE | C13: =Coefficients!$H$4*(INDEX(Coefficients!$D$2:$D$40,MATCH($A13,Coefficients!$A$2:$A$40,0))+INDEX(Coefficients!$C$2:$C$40,MATCH($A13,Coefficients!$A$2:$A$40,0))/0.25+Coefficients!$H$2*0.25) -> 0.3488123 | D13: =Coefficients!$H$4*(INDEX(Coefficients!$D$2:$D$40,MATCH($A13,Coefficients!$A$2:$A$40,0))+INDEX(Coefficients!$C$2:$C$40,MATCH($A13,Coefficients!$A$2:$A$40,0))/0.35+Coefficients!$H$2*0.35) -> 0.31491775 | E13: =Coefficients!$H$4*(INDEX(Coefficients!$D$2:$D$40,MATCH($A13,Coefficients!$A$2:$A$40,0))+INDEX(Coefficients!$C$2:$C$40,MATCH($A13,Coefficients!$A$2:$A$40,0))/0.5+Coefficients!$H$2*0.5) -> 0.29522939 | F13: =Coefficients!$H$4*(INDEX(Coefficients!$D$2:$D$40,MATCH($A13,Coefficients!$A$2:$A$40,0))+INDEX(Coefficients!$C$2:$C$40,MATCH($A13,Coefficients!$A$2:$A$40,0))/0.75+Coefficients!$H$2*0.75) -> 0.29010741 | G13: 0.312 | H13: 0.354
A14: JCB 448 (125 kVA) | B14: KSA | C14: =Coefficients!$H$3*(INDEX(Coefficients!$D$2:$D$40,MATCH($A14,Coefficients!$A$2:$A$40,0))+INDEX(Coefficients!$C$2:$C$40,MATCH($A14,Coefficients!$A$2:$A$40,0))/0.25+Coefficients!$H$2*0.25) -> 0.43497467 | D14: =Coefficients!$H$3*(INDEX(Coefficients!$D$2:$D$40,MATCH($A14,Coefficients!$A$2:$A$40,0))+INDEX(Coefficients!$C$2:$C$40,MATCH($A14,Coefficients!$A$2:$A$40,0))/0.35+Coefficients!$H$2*0.35) -> 0.39524217 | E14: =Coefficients!$H$3*(INDEX(Coefficients!$D$2:$D$40,MATCH($A14,Coefficients!$A$2:$A$40,0))+INDEX(Coefficients!$C$2:$C$40,MATCH($A14,Coefficients!$A$2:$A$40,0))/0.5+Coefficients!$H$2*0.5) -> 0.37166231 | F14: =Coefficients!$H$3*(INDEX(Coefficients!$D$2:$D$40,MATCH($A14,Coefficients!$A$2:$A$40,0))+INDEX(Coefficients!$C$2:$C$40,MATCH($A14,Coefficients!$A$2:$A$40,0))/0.75+Coefficients!$H$2*0.75) -> 0.36437937 | G14: 0.369 | H14: 0.415
A15: JCB 448 (125 kVA) | B15: UAE | C15: =Coefficients!$H$4*(INDEX(Coefficients!$D$2:$D$40,MATCH($A15,Coefficients!$A$2:$A$40,0))+INDEX(Coefficients!$C$2:$C$40,MATCH($A15,Coefficients!$A$2:$A$40,0))/0.25+Coefficients!$H$2*0.25) -> 0.40091658 | D15: =Coefficients!$H$4*(INDEX(Coefficients!$D$2:$D$40,MATCH($A15,Coefficients!$A$2:$A$40,0))+INDEX(Coefficients!$C$2:$C$40,MATCH($A15,Coefficients!$A$2:$A$40,0))/0.35+Coefficients!$H$2*0.35) -> 0.36429509 | E15: =Coefficients!$H$4*(INDEX(Coefficients!$D$2:$D$40,MATCH($A15,Coefficients!$A$2:$A$40,0))+INDEX(Coefficients!$C$2:$C$40,MATCH($A15,Coefficients!$A$2:$A$40,0))/0.5+Coefficients!$H$2*0.5) -> 0.34256151 | F15: =Coefficients!$H$4*(INDEX(Coefficients!$D$2:$D$40,MATCH($A15,Coefficients!$A$2:$A$40,0))+INDEX(Coefficients!$C$2:$C$40,MATCH($A15,Coefficients!$A$2:$A$40,0))/0.75+Coefficients!$H$2*0.75) -> 0.33584881 | G15: 0.342 | H15: 0.389
A16: JCB 448 (60 kVA) | B16: KSA | C16: =Coefficients!$H$3*(INDEX(Coefficients!$D$2:$D$40,MATCH($A16,Coefficients!$A$2:$A$40,0))+INDEX(Coefficients!$C$2:$C$40,MATCH($A16,Coefficients!$A$2:$A$40,0))/0.25+Coefficients!$H$2*0.25) -> 0.34049215 | D16: =Coefficients!$H$3*(INDEX(Coefficients!$D$2:$D$40,MATCH($A16,Coefficients!$A$2:$A$40,0))+INDEX(Coefficients!$C$2:$C$40,MATCH($A16,Coefficients!$A$2:$A$40,0))/0.35+Coefficients!$H$2*0.35) -> 0.33919869 | E16: =Coefficients!$H$3*(INDEX(Coefficients!$D$2:$D$40,MATCH($A16,Coefficients!$A$2:$A$40,0))+INDEX(Coefficients!$C$2:$C$40,MATCH($A16,Coefficients!$A$2:$A$40,0))/0.5+Coefficients!$H$2*0.5) -> 0.34444813 | F16: =Coefficients!$H$3*(INDEX(Coefficients!$D$2:$D$40,MATCH($A16,Coefficients!$A$2:$A$40,0))+INDEX(Coefficients!$C$2:$C$40,MATCH($A16,Coefficients!$A$2:$A$40,0))/0.75+Coefficients!$H$2*0.75) -> 0.35958796 | G16: 0.301 | H16: 0.349
A17: JCB 448 (60 kVA) | B17: UAE | C17: =Coefficients!$H$4*(INDEX(Coefficients!$D$2:$D$40,MATCH($A17,Coefficients!$A$2:$A$40,0))+INDEX(Coefficients!$C$2:$C$40,MATCH($A17,Coefficients!$A$2:$A$40,0))/0.25+Coefficients!$H$2*0.25) -> 0.31383194 | D17: =Coefficients!$H$4*(INDEX(Coefficients!$D$2:$D$40,MATCH($A17,Coefficients!$A$2:$A$40,0))+INDEX(Coefficients!$C$2:$C$40,MATCH($A17,Coefficients!$A$2:$A$40,0))/0.35+Coefficients!$H$2*0.35) -> 0.31263976 | E17: =Coefficients!$H$4*(INDEX(Coefficients!$D$2:$D$40,MATCH($A17,Coefficients!$A$2:$A$40,0))+INDEX(Coefficients!$C$2:$C$40,MATCH($A17,Coefficients!$A$2:$A$40,0))/0.5+Coefficients!$H$2*0.5) -> 0.31747817 | F17: =Coefficients!$H$4*(INDEX(Coefficients!$D$2:$D$40,MATCH($A17,Coefficients!$A$2:$A$40,0))+INDEX(Coefficients!$C$2:$C$40,MATCH($A17,Coefficients!$A$2:$A$40,0))/0.75+Coefficients!$H$2*0.75) -> 0.33143257 | G17: 0.28 | H17: 0.329
A18: JD 6068 (220 kVA) | B18: KSA | C18: =Coefficients!$H$3*(INDEX(Coefficients!$D$2:$D$40,MATCH($A18,Coefficients!$A$2:$A$40,0))+INDEX(Coefficients!$C$2:$C$40,MATCH($A18,Coefficients!$A$2:$A$40,0))/0.25+Coefficients!$H$2*0.25) -> 0.48912109 | D18: =Coefficients!$H$3*(INDEX(Coefficients!$D$2:$D$40,MATCH($A18,Coefficients!$A$2:$A$40,0))+INDEX(Coefficients!$C$2:$C$40,MATCH($A18,Coefficients!$A$2:$A$40,0))/0.35+Coefficients!$H$2*0.35) -> 0.44044167 | E18: =Coefficients!$H$3*(INDEX(Coefficients!$D$2:$D$40,MATCH($A18,Coefficients!$A$2:$A$40,0))+INDEX(Coefficients!$C$2:$C$40,MATCH($A18,Coefficients!$A$2:$A$40,0))/0.5+Coefficients!$H$2*0.5) -> 0.41015164 | F18: =Coefficients!$H$3*(INDEX(Coefficients!$D$2:$D$40,MATCH($A18,Coefficients!$A$2:$A$40,0))+INDEX(Coefficients!$C$2:$C$40,MATCH($A18,Coefficients!$A$2:$A$40,0))/0.75+Coefficients!$H$2*0.75) -> 0.39764967 | G18: 0.415 | H18: 0.45
A19: JD 6068 (220 kVA) | B19: UAE | C19: =Coefficients!$H$4*(INDEX(Coefficients!$D$2:$D$40,MATCH($A19,Coefficients!$A$2:$A$40,0))+INDEX(Coefficients!$C$2:$C$40,MATCH($A19,Coefficients!$A$2:$A$40,0))/0.25+Coefficients!$H$2*0.25) -> 0.45082338 | D19: =Coefficients!$H$4*(INDEX(Coefficients!$D$2:$D$40,MATCH($A19,Coefficients!$A$2:$A$40,0))+INDEX(Coefficients!$C$2:$C$40,MATCH($A19,Coefficients!$A$2:$A$40,0))/0.35+Coefficients!$H$2*0.35) -> 0.40595552 | E19: =Coefficients!$H$4*(INDEX(Coefficients!$D$2:$D$40,MATCH($A19,Coefficients!$A$2:$A$40,0))+INDEX(Coefficients!$C$2:$C$40,MATCH($A19,Coefficients!$A$2:$A$40,0))/0.5+Coefficients!$H$2*0.5) -> 0.37803716 | F19: =Coefficients!$H$4*(INDEX(Coefficients!$D$2:$D$40,MATCH($A19,Coefficients!$A$2:$A$40,0))+INDEX(Coefficients!$C$2:$C$40,MATCH($A19,Coefficients!$A$2:$A$40,0))/0.75+Coefficients!$H$2*0.75) -> 0.36651408 | G19: 0.387 | H19: 0.418
A20: JD 6090 (300 kVA) | B20: KSA | C20: =Coefficients!$H$3*(INDEX(Coefficients!$D$2:$D$40,MATCH($A20,Coefficients!$A$2:$A$40,0))+INDEX(Coefficients!$C$2:$C$40,MATCH($A20,Coefficients!$A$2:$A$40,0))/0.25+Coefficients!$H$2*0.25) -> 0.50127824 | D20: =Coefficients!$H$3*(INDEX(Coefficients!$D$2:$D$40,MATCH($A20,Coefficients!$A$2:$A$40,0))+INDEX(Coefficients!$C$2:$C$40,MATCH($A20,Coefficients!$A$2:$A$40,0))/0.35+Coefficients!$H$2*0.35) -> 0.4585971 | E20: =Coefficients!$H$3*(INDEX(Coefficients!$D$2:$D$40,MATCH($A20,Coefficients!$A$2:$A$40,0))+INDEX(Coefficients!$C$2:$C$40,MATCH($A20,Coefficients!$A$2:$A$40,0))/0.5+Coefficients!$H$2*0.5) -> 0.43280578 | F20: =Coefficients!$H$3*(INDEX(Coefficients!$D$2:$D$40,MATCH($A20,Coefficients!$A$2:$A$40,0))+INDEX(Coefficients!$C$2:$C$40,MATCH($A20,Coefficients!$A$2:$A$40,0))/0.75+Coefficients!$H$2*0.75) -> 0.4238028 | G20: 0.421 | H20: 0.492
A21: JD 6090 (300 kVA) | B21: UAE | C21: =Coefficients!$H$4*(INDEX(Coefficients!$D$2:$D$40,MATCH($A21,Coefficients!$A$2:$A$40,0))+INDEX(Coefficients!$C$2:$C$40,MATCH($A21,Coefficients!$A$2:$A$40,0))/0.25+Coefficients!$H$2*0.25) -> 0.46202864 | D21: =Coefficients!$H$4*(INDEX(Coefficients!$D$2:$D$40,MATCH($A21,Coefficients!$A$2:$A$40,0))+INDEX(Coefficients!$C$2:$C$40,MATCH($A21,Coefficients!$A$2:$A$40,0))/0.35+Coefficients!$H$2*0.35) -> 0.42268939 | E21: =Coefficients!$H$4*(INDEX(Coefficients!$D$2:$D$40,MATCH($A21,Coefficients!$A$2:$A$40,0))+INDEX(Coefficients!$C$2:$C$40,MATCH($A21,Coefficients!$A$2:$A$40,0))/0.5+Coefficients!$H$2*0.5) -> 0.3989175 | F21: =Coefficients!$H$4*(INDEX(Coefficients!$D$2:$D$40,MATCH($A21,Coefficients!$A$2:$A$40,0))+INDEX(Coefficients!$C$2:$C$40,MATCH($A21,Coefficients!$A$2:$A$40,0))/0.75+Coefficients!$H$2*0.75) -> 0.39061945 | G21: 0.395 | H21: 0.452
A22: Scania DC13 (500 kVA) | B22: KSA | C22: =Coefficients!$H$3*(INDEX(Coefficients!$D$2:$D$40,MATCH($A22,Coefficients!$A$2:$A$40,0))+INDEX(Coefficients!$C$2:$C$40,MATCH($A22,Coefficients!$A$2:$A$40,0))/0.25+Coefficients!$H$2*0.25) -> 0.30737419 | D22: =Coefficients!$H$3*(INDEX(Coefficients!$D$2:$D$40,MATCH($A22,Coefficients!$A$2:$A$40,0))+INDEX(Coefficients!$C$2:$C$40,MATCH($A22,Coefficients!$A$2:$A$40,0))/0.35+Coefficients!$H$2*0.35) -> 0.28445593 | E22: =Coefficients!$H$3*(INDEX(Coefficients!$D$2:$D$40,MATCH($A22,Coefficients!$A$2:$A$40,0))+INDEX(Coefficients!$C$2:$C$40,MATCH($A22,Coefficients!$A$2:$A$40,0))/0.5+Coefficients!$H$2*0.5) -> 0.27348677 | F22: =Coefficients!$H$3*(INDEX(Coefficients!$D$2:$D$40,MATCH($A22,Coefficients!$A$2:$A$40,0))+INDEX(Coefficients!$C$2:$C$40,MATCH($A22,Coefficients!$A$2:$A$40,0))/0.75+Coefficients!$H$2*0.75) -> 0.27601213 | G22: 0.283 | H22: 0.286
A23: Scania DC13 (500 kVA) | B23: UAE | C23: =Coefficients!$H$4*(INDEX(Coefficients!$D$2:$D$40,MATCH($A23,Coefficients!$A$2:$A$40,0))+INDEX(Coefficients!$C$2:$C$40,MATCH($A23,Coefficients!$A$2:$A$40,0))/0.25+Coefficients!$H$2*0.25) -> 0.28330709 | D23: =Coefficients!$H$4*(INDEX(Coefficients!$D$2:$D$40,MATCH($A23,Coefficients!$A$2:$A$40,0))+INDEX(Coefficients!$C$2:$C$40,MATCH($A23,Coefficients!$A$2:$A$40,0))/0.35+Coefficients!$H$2*0.35) -> 0.26218331 | E23: =Coefficients!$H$4*(INDEX(Coefficients!$D$2:$D$40,MATCH($A23,Coefficients!$A$2:$A$40,0))+INDEX(Coefficients!$C$2:$C$40,MATCH($A23,Coefficients!$A$2:$A$40,0))/0.5+Coefficients!$H$2*0.5) -> 0.25207302 | F23: =Coefficients!$H$4*(INDEX(Coefficients!$D$2:$D$40,MATCH($A23,Coefficients!$A$2:$A$40,0))+INDEX(Coefficients!$C$2:$C$40,MATCH($A23,Coefficients!$A$2:$A$40,0))/0.75+Coefficients!$H$2*0.75) -> 0.25440065 | G23: 0.26 | H23: 0.276
A24: Volvo TAD1651 (500 kVA) | B24: KSA | C24: =Coefficients!$H$3*(INDEX(Coefficients!$D$2:$D$40,MATCH($A24,Coefficients!$A$2:$A$40,0))+INDEX(Coefficients!$C$2:$C$40,MATCH($A24,Coefficients!$A$2:$A$40,0))/0.25+Coefficients!$H$2*0.25) -> 0.37187891 | D24: =Coefficients!$H$3*(INDEX(Coefficients!$D$2:$D$40,MATCH($A24,Coefficients!$A$2:$A$40,0))+INDEX(Coefficients!$C$2:$C$40,MATCH($A24,Coefficients!$A$2:$A$40,0))/0.35+Coefficients!$H$2*0.35) -> 0.33990011 | E24: =Coefficients!$H$3*(INDEX(Coefficients!$D$2:$D$40,MATCH($A24,Coefficients!$A$2:$A$40,0))+INDEX(Coefficients!$C$2:$C$40,MATCH($A24,Coefficients!$A$2:$A$40,0))/0.5+Coefficients!$H$2*0.5) -> 0.32213555 | F24: =Coefficients!$H$3*(INDEX(Coefficients!$D$2:$D$40,MATCH($A24,Coefficients!$A$2:$A$40,0))+INDEX(Coefficients!$C$2:$C$40,MATCH($A24,Coefficients!$A$2:$A$40,0))/0.75+Coefficients!$H$2*0.75) -> 0.3193756 | G24: 0.333 | H24: 0.346
A25: Volvo TAD1651 (500 kVA) | B25: UAE | C25: =Coefficients!$H$4*(INDEX(Coefficients!$D$2:$D$40,MATCH($A25,Coefficients!$A$2:$A$40,0))+INDEX(Coefficients!$C$2:$C$40,MATCH($A25,Coefficients!$A$2:$A$40,0))/0.25+Coefficients!$H$2*0.25) -> 0.34276115 | D25: =Coefficients!$H$4*(INDEX(Coefficients!$D$2:$D$40,MATCH($A25,Coefficients!$A$2:$A$40,0))+INDEX(Coefficients!$C$2:$C$40,MATCH($A25,Coefficients!$A$2:$A$40,0))/0.35+Coefficients!$H$2*0.35) -> 0.31328626 | E25: =Coefficients!$H$4*(INDEX(Coefficients!$D$2:$D$40,MATCH($A25,Coefficients!$A$2:$A$40,0))+INDEX(Coefficients!$C$2:$C$40,MATCH($A25,Coefficients!$A$2:$A$40,0))/0.5+Coefficients!$H$2*0.5) -> 0.29691264 | F25: =Coefficients!$H$4*(INDEX(Coefficients!$D$2:$D$40,MATCH($A25,Coefficients!$A$2:$A$40,0))+INDEX(Coefficients!$C$2:$C$40,MATCH($A25,Coefficients!$A$2:$A$40,0))/0.75+Coefficients!$H$2*0.75) -> 0.2943688 | G25: 0.311 | H25: 0.326
A26: unlisted 200–220 kVA | B26: KSA | C26: =Coefficients!$H$3*(INDEX(Coefficients!$D$2:$D$40,MATCH($A26,Coefficients!$A$2:$A$40,0))+INDEX(Coefficients!$C$2:$C$40,MATCH($A26,Coefficients!$A$2:$A$40,0))/0.25+Coefficients!$H$2*0.25) -> 0.45856067 | D26: =Coefficients!$H$3*(INDEX(Coefficients!$D$2:$D$40,MATCH($A26,Coefficients!$A$2:$A$40,0))+INDEX(Coefficients!$C$2:$C$40,MATCH($A26,Coefficients!$A$2:$A$40,0))/0.35+Coefficients!$H$2*0.35) -> 0.46685337 | E26: =Coefficients!$H$3*(INDEX(Coefficients!$D$2:$D$40,MATCH($A26,Coefficients!$A$2:$A$40,0))+INDEX(Coefficients!$C$2:$C$40,MATCH($A26,Coefficients!$A$2:$A$40,0))/0.5+Coefficients!$H$2*0.5) -> 0.47929243 | F26: =Coefficients!$H$3*(INDEX(Coefficients!$D$2:$D$40,MATCH($A26,Coefficients!$A$2:$A$40,0))+INDEX(Coefficients!$C$2:$C$40,MATCH($A26,Coefficients!$A$2:$A$40,0))/0.75+Coefficients!$H$2*0.75) -> 0.50002419 | G26: 0.405 | H26: 0.496
A27: unlisted 200–220 kVA | B27: UAE | C27: =Coefficients!$H$4*(INDEX(Coefficients!$D$2:$D$40,MATCH($A27,Coefficients!$A$2:$A$40,0))+INDEX(Coefficients!$C$2:$C$40,MATCH($A27,Coefficients!$A$2:$A$40,0))/0.25+Coefficients!$H$2*0.25) -> 0.42265581 | D27: =Coefficients!$H$4*(INDEX(Coefficients!$D$2:$D$40,MATCH($A27,Coefficients!$A$2:$A$40,0))+INDEX(Coefficients!$C$2:$C$40,MATCH($A27,Coefficients!$A$2:$A$40,0))/0.35+Coefficients!$H$2*0.35) -> 0.4302992 | E27: =Coefficients!$H$4*(INDEX(Coefficients!$D$2:$D$40,MATCH($A27,Coefficients!$A$2:$A$40,0))+INDEX(Coefficients!$C$2:$C$40,MATCH($A27,Coefficients!$A$2:$A$40,0))/0.5+Coefficients!$H$2*0.5) -> 0.44176429 | F27: =Coefficients!$H$4*(INDEX(Coefficients!$D$2:$D$40,MATCH($A27,Coefficients!$A$2:$A$40,0))+INDEX(Coefficients!$C$2:$C$40,MATCH($A27,Coefficients!$A$2:$A$40,0))/0.75+Coefficients!$H$2*0.75) -> 0.46087278 | G27: 0.377 | H27: 0.463
A28: unlisted 300 kVA | B28: KSA | C28: =Coefficients!$H$3*(INDEX(Coefficients!$D$2:$D$40,MATCH($A28,Coefficients!$A$2:$A$40,0))+INDEX(Coefficients!$C$2:$C$40,MATCH($A28,Coefficients!$A$2:$A$40,0))/0.25+Coefficients!$H$2*0.25) -> 0.36442295 | D28: =Coefficients!$H$3*(INDEX(Coefficients!$D$2:$D$40,MATCH($A28,Coefficients!$A$2:$A$40,0))+INDEX(Coefficients!$C$2:$C$40,MATCH($A28,Coefficients!$A$2:$A$40,0))/0.35+Coefficients!$H$2*0.35) -> 0.30950548 | E28: =Coefficients!$H$3*(INDEX(Coefficients!$D$2:$D$40,MATCH($A28,Coefficients!$A$2:$A$40,0))+INDEX(Coefficients!$C$2:$C$40,MATCH($A28,Coefficients!$A$2:$A$40,0))/0.5+Coefficients!$H$2*0.5) -> 0.27453691 | F28: =Coefficients!$H$3*(INDEX(Coefficients!$D$2:$D$40,MATCH($A28,Coefficients!$A$2:$A$40,0))+INDEX(Coefficients!$C$2:$C$40,MATCH($A28,Coefficients!$A$2:$A$40,0))/0.75+Coefficients!$H$2*0.75) -> 0.25839608 | G28: 0.301 | H28: 0.318
A29: unlisted 300 kVA | B29: UAE | C29: =Coefficients!$H$4*(INDEX(Coefficients!$D$2:$D$40,MATCH($A29,Coefficients!$A$2:$A$40,0))+INDEX(Coefficients!$C$2:$C$40,MATCH($A29,Coefficients!$A$2:$A$40,0))/0.25+Coefficients!$H$2*0.25) -> 0.33588898 | D29: =Coefficients!$H$4*(INDEX(Coefficients!$D$2:$D$40,MATCH($A29,Coefficients!$A$2:$A$40,0))+INDEX(Coefficients!$C$2:$C$40,MATCH($A29,Coefficients!$A$2:$A$40,0))/0.35+Coefficients!$H$2*0.35) -> 0.2852715 | E29: =Coefficients!$H$4*(INDEX(Coefficients!$D$2:$D$40,MATCH($A29,Coefficients!$A$2:$A$40,0))+INDEX(Coefficients!$C$2:$C$40,MATCH($A29,Coefficients!$A$2:$A$40,0))/0.5+Coefficients!$H$2*0.5) -> 0.25304094 | F29: =Coefficients!$H$4*(INDEX(Coefficients!$D$2:$D$40,MATCH($A29,Coefficients!$A$2:$A$40,0))+INDEX(Coefficients!$C$2:$C$40,MATCH($A29,Coefficients!$A$2:$A$40,0))/0.75+Coefficients!$H$2*0.75) -> 0.23816391 | G29: 0.278 | H29: 0.302
A30: unlisted 500 kVA | B30: KSA | C30: =Coefficients!$H$3*(INDEX(Coefficients!$D$2:$D$40,MATCH($A30,Coefficients!$A$2:$A$40,0))+INDEX(Coefficients!$C$2:$C$40,MATCH($A30,Coefficients!$A$2:$A$40,0))/0.25+Coefficients!$H$2*0.25) -> 0.36494945 | D30: =Coefficients!$H$3*(INDEX(Coefficients!$D$2:$D$40,MATCH($A30,Coefficients!$A$2:$A$40,0))+INDEX(Coefficients!$C$2:$C$40,MATCH($A30,Coefficients!$A$2:$A$40,0))/0.35+Coefficients!$H$2*0.35) -> 0.31833779 | E30: =Coefficients!$H$3*(INDEX(Coefficients!$D$2:$D$40,MATCH($A30,Coefficients!$A$2:$A$40,0))+INDEX(Coefficients!$C$2:$C$40,MATCH($A30,Coefficients!$A$2:$A$40,0))/0.5+Coefficients!$H$2*0.5) -> 0.28959858 | F30: =Coefficients!$H$3*(INDEX(Coefficients!$D$2:$D$40,MATCH($A30,Coefficients!$A$2:$A$40,0))+INDEX(Coefficients!$C$2:$C$40,MATCH($A30,Coefficients!$A$2:$A$40,0))/0.75+Coefficients!$H$2*0.75) -> 0.2783028 | G30: 0.304 | H30: 0.333
A31: unlisted 500 kVA | B31: UAE | C31: =Coefficients!$H$4*(INDEX(Coefficients!$D$2:$D$40,MATCH($A31,Coefficients!$A$2:$A$40,0))+INDEX(Coefficients!$C$2:$C$40,MATCH($A31,Coefficients!$A$2:$A$40,0))/0.25+Coefficients!$H$2*0.25) -> 0.33637426 | D31: =Coefficients!$H$4*(INDEX(Coefficients!$D$2:$D$40,MATCH($A31,Coefficients!$A$2:$A$40,0))+INDEX(Coefficients!$C$2:$C$40,MATCH($A31,Coefficients!$A$2:$A$40,0))/0.35+Coefficients!$H$2*0.35) -> 0.29341225 | E31: =Coefficients!$H$4*(INDEX(Coefficients!$D$2:$D$40,MATCH($A31,Coefficients!$A$2:$A$40,0))+INDEX(Coefficients!$C$2:$C$40,MATCH($A31,Coefficients!$A$2:$A$40,0))/0.5+Coefficients!$H$2*0.5) -> 0.26692329 | F31: =Coefficients!$H$4*(INDEX(Coefficients!$D$2:$D$40,MATCH($A31,Coefficients!$A$2:$A$40,0))+INDEX(Coefficients!$C$2:$C$40,MATCH($A31,Coefficients!$A$2:$A$40,0))/0.75+Coefficients!$H$2*0.75) -> 0.25651196 | G31: 0.283 | H31: 0.31
A32: unlisted ≤125 kVA | B32: KSA | C32: =Coefficients!$H$3*(INDEX(Coefficients!$D$2:$D$40,MATCH($A32,Coefficients!$A$2:$A$40,0))+INDEX(Coefficients!$C$2:$C$40,MATCH($A32,Coefficients!$A$2:$A$40,0))/0.25+Coefficients!$H$2*0.25) -> 0.43908476 | D32: =Coefficients!$H$3*(INDEX(Coefficients!$D$2:$D$40,MATCH($A32,Coefficients!$A$2:$A$40,0))+INDEX(Coefficients!$C$2:$C$40,MATCH($A32,Coefficients!$A$2:$A$40,0))/0.35+Coefficients!$H$2*0.35) -> 0.41451796 | E32: =Coefficients!$H$3*(INDEX(Coefficients!$D$2:$D$40,MATCH($A32,Coefficients!$A$2:$A$40,0))+INDEX(Coefficients!$C$2:$C$40,MATCH($A32,Coefficients!$A$2:$A$40,0))/0.5+Coefficients!$H$2*0.5) -> 0.40231238 | F32: =Coefficients!$H$3*(INDEX(Coefficients!$D$2:$D$40,MATCH($A32,Coefficients!$A$2:$A$40,0))+INDEX(Coefficients!$C$2:$C$40,MATCH($A32,Coefficients!$A$2:$A$40,0))/0.75+Coefficients!$H$2*0.75) -> 0.4038761 | G32: 0.414 | H32: 0.42
A33: unlisted ≤125 kVA | B33: UAE | C33: =Coefficients!$H$4*(INDEX(Coefficients!$D$2:$D$40,MATCH($A33,Coefficients!$A$2:$A$40,0))+INDEX(Coefficients!$C$2:$C$40,MATCH($A33,Coefficients!$A$2:$A$40,0))/0.25+Coefficients!$H$2*0.25) -> 0.40470485 | D33: =Coefficients!$H$4*(INDEX(Coefficients!$D$2:$D$40,MATCH($A33,Coefficients!$A$2:$A$40,0))+INDEX(Coefficients!$C$2:$C$40,MATCH($A33,Coefficients!$A$2:$A$40,0))/0.35+Coefficients!$H$2*0.35) -> 0.3820616 | E33: =Coefficients!$H$4*(INDEX(Coefficients!$D$2:$D$40,MATCH($A33,Coefficients!$A$2:$A$40,0))+INDEX(Coefficients!$C$2:$C$40,MATCH($A33,Coefficients!$A$2:$A$40,0))/0.5+Coefficients!$H$2*0.5) -> 0.37081171 | F33: =Coefficients!$H$4*(INDEX(Coefficients!$D$2:$D$40,MATCH($A33,Coefficients!$A$2:$A$40,0))+INDEX(Coefficients!$C$2:$C$40,MATCH($A33,Coefficients!$A$2:$A$40,0))/0.75+Coefficients!$H$2*0.75) -> 0.37225299 | G33: 0.38 | H33: 0.403
A35: Low/high = 10th–90th percentile from 120 site-bootstrap refits. Loading = unit output ÷ rated kW (kVA × 0.8).

Sheet Site check
A1: Site | B1: Months | C1: Actual fuel (L) | D1: Predicted, site left out (L) | E1: Error | F1: |Error|
A2: KSA - Sprint - I | B2: 3 | C2: 21907 | D2: 18611 | E2: =D2/C2-1 -> -0.15045419 | F2: =ABS(E2) -> 0.15045419
A3: UAE - Innovo Build - S | B3: 10 | C3: 145370 | D3: 131054 | E3: =D3/C3-1 -> -0.098479741 | F3: =ABS(E3) -> 0.098479741
A4: KSA - MBL Opera - S | B4: 19 | C4: 169614 | D4: 154997 | E4: =D4/C4-1 -> -0.086178028 | F4: =ABS(E4) -> 0.086178028
A5: UAE - Specialist - C | B5: 7 | C5: 238320 | D5: 218074 | E5: =D5/C5-1 -> -0.084953004 | F5: =ABS(E5) -> 0.084953004
A6: UAE - EAST VILLE Fujeirah - C | B6: 14 | C6: 1047206 | D6: 983049 | E6: =D6/C6-1 -> -0.061264928 | F6: =ABS(E6) -> 0.061264928
A7: UAE - Galfar - C | B7: 11 | C7: 1342047 | D7: 1264903 | E7: =D7/C7-1 -> -0.057482339 | F7: =ABS(E7) -> 0.057482339
A8: KSA - Namareq KAEC - C | B8: 15 | C8: 2406769 | D8: 2270959 | E8: =D8/C8-1 -> -0.056428349 | F8: =ABS(E8) -> 0.056428349
A9: UAE - ENATA - I | B9: 1 | C9: 21372 | D9: 20336 | E9: =D9/C9-1 -> -0.04847464 | F9: =ABS(E9) -> 0.04847464
A10: UAE - Intermass - S | B10: 16 | C10: 124843 | D10: 120671 | E10: =D10/C10-1 -> -0.033417973 | F10: =ABS(E10) -> 0.033417973
A11: KSA - Crystal Rabigh - C | B11: 3 | C11: 335751 | D11: 324643 | E11: =D11/C11-1 -> -0.033084041 | F11: =ABS(E11) -> 0.033084041
A12: KSA - ARCC (H) - C | B12: 8 | C12: 603167 | D12: 586950 | E12: =D12/C12-1 -> -0.026886418 | F12: =ABS(E12) -> 0.026886418
A13: UAE - Natural Fragrances - I | B13: 1 | C13: 8705 | D13: 8557 | E13: =D13/C13-1 -> -0.017001723 | F13: =ABS(E13) -> 0.017001723
... A38: KSA - KENT - C | B38: 8 | C38: 744631 | D38: 881268 | E38: =D38/C38-1 -> 0.18349626 | F38: =ABS(E38) -> 0.18349626
A40: Median |error| | E40: =MEDIAN(F2:F38) -> 0.033417973
A41: Each site predicted with curves fitted on the other 36 sites, using the units that actually ran. KENT is the only Scania DC13 site, so left out it falls back to a generic 500 kVA curve.

Sheet Fleet by family
A1: Device | B1: Family | C1: Make | D1: Engine | E1: Year | F1: Running hours | G1: Country
A2: GS-1250-003 | B2: Cummins KTA50 (1250 kVA) | C2: CUMMINS | D2: KTA50-G3 | E2: 2009 | F2: 41619 | G2: KSA
A3: GS-1250-006 | B3: Cummins KTA50 (1250 kVA) | C3: CUMMINS | D3: KTA50 G3 | E3: 2009 | F3: 13634 | G3: UAE
A4: GS-1250-010 | B4: Cummins KTA50 (1250 kVA) | C4: CUMMINS | D4: KTA50-G3 | E4: 2011 | F4: 15261 | G4: KSA
A5: GS-1250-029 | B5: Cummins KTA50 (1250 kVA) | C5: CUMMINS | D5: KTA50 G3 | E5: 2013 | F5: 20589 | G5: UAE
A6: GS-1250-030 | B6: Cummins KTA50 (1250 kVA) | C6: CUMMINS | D6: KTA50 G3 | E6: 2013 | F6: 6687 | G6: UAE
A7: GS-1250-032 | B7: Cummins KTA50 (1250 kVA) | C7: CUMMINS | D7: KTA50-G3 | E7: 2013 | F7: 9453 | G7: KSA
A8: GS-1250-036 | B8: Cummins KTA50 (1250 kVA) | C8: CUMMINS | D8: KTA50 G3 | E8: 2013 | F8: 9987 | G8: UAE
A9: GS-1250-038 | B9: Cummins KTA50 (1250 kVA) | C9: CUMMINS | D9: KTA50 G3 | E9: 2013 | F9: 9525 | G9: UAE
A10: GS-1250-041 | B10: Cummins KTA50 (1250 kVA) | C10: CUMMINS | D10: KTA50-G3 | E10: 2014 | F10: 16520 | G10: KSA
A11: GS-1250-056 | B11: Cummins KTA50 (1250 kVA) | C11: CUMMINS | D11: KTA50-G3 | F11: 8912 | G11: KSA
A12: GS-1250-058 | B12: Cummins KTA50 (1250 kVA) | C12: CUMMINS | D12: KTA50-G3 | F12: 8948 | G12: KSA
A13: GS-1250-059 | B13: Cummins KTA50 (1250 kVA) | C13: CUMMINS | D13: KTA50-G3 | F13: 16950 | G13: KSA
A14: GS-1250-060 | B14: Cummins KTA50 (1250 kVA) | C14: CUMMINS | D14: KTA50-G3 | F14: 37209 | G14: KSA
A15: GS-1250-061 | B15: Cummins KTA50 (1250 kVA) | C15: CUMMINS | D15: KTA50-G3 | F15: 29707 | G15: KSA
A16: GS-1250-064 | B16: Cummins KTA50 (1250 kVA) | C16: CUMMINS | D16: KTA50-G3 | F16: 13564 | G16: KSA
A17: GS-1250-068 | B17: Cummins KTA50 (1250 kVA) | C17: CUMMINS | D17: KTA50-G3 | F17: 19262 | G17: KSA
A18: GS-1250-071 | B18: Cummins KTA50 (1250 kVA) | C18: CUMMINS | D18: KTA50-G3 | F18: 2788 | G18: KSA
A19: GS-1250-075 | B19: Cummins KTA50 (1250 kVA) | C19: CUMMINS | D19: KTA50-G3 | F19: 31595 | G19: KSA
A20: GS-1250-076 | B20: Cummins KTA50 (1250 kVA) | C20: CUMMINS | D20: KTA50 G3 | F20: 17644 | G20: UAE
A21: GS-1250-083 | B21: Cummins KTA50 (1250 kVA) | C21: CUMMINS | D21: KTA50 G3 | F21: 16516 | G21: UAE
A22: GS-1250-086 | B22: Cummins KTA50 (1250 kVA) | C22: CUMMINS | D22: KTA50 G3 | F22: 17722 | G22: UAE
... A24: GS-1250-092 | B24: Cummins KTA50 (1250 kVA) | C24: CUMMINS | D24: KTA50-G3 | F24: 24655 | G24: KSA
A25: GS-350-019 | B25: Cummins QSG12 (350 kVA) | C25: CUMMINS | D25: QSG12-G1 | E25: 2024 | F25: 9540 | G25: UAE
A26: GS-350-020 | B26: Cummins QSG12 (350 kVA) | C26: CUMMINS | D26: QSG12-G1 | E26: 2024 | F26: 5692 | G26: UAE
A27: GS-350-021 | B27: Cummins QSG12 (350 kVA) | C27: CUMMINS | D27: QSG12-G1 | E27: 2024 | F27: 7414 | G27: UAE
A28: GS-350-022 | B28: Cummins QSG12 (350 kVA) | C28: CUMMINS | D28: QSG12-G1 | E28: 2024 | F28: 5948 | G28: UAE
A29: GS-800-024 | B29: Cummins QSK23 (800 kVA) | C29: CUMMINS | D29: QSK23-G3 | E29: 2024 | F29: 8987 | G29: UAE
A30: GS-800-025 | B30: Cummins QSK23 (800 kVA) | C30: CUMMINS | D30: QSK23-G3 | E30: 2024 | F30: 6116 | G30: UAE
A31: GS-800-026 | B31: Cummins QSK23 (800 kVA) | C31: CUMMINS | D31: QSK23-G3 | E31: 2024 | F31: 8049 | G31: UAE
A32: GS-800-027 | B32: Cummins QSK23 (800 kVA) | C32: CUMMINS | D32: QSK23-G3 | E32: 2024 | F32: 4375 | G32: UAE
A33: GS-800-028 | B33: Cummins QSK23 (800 kVA) | C33: CUMMINS | D33: QSK23-G3 | E33: 2024 | F33: 8272 | G33: UAE
A34: GS-800-029 | B34: Cummins QSK23 (800 kVA) | C34: CUMMINS | D34: QSK23-G3 | E34: 2024 | F34: 4305 | G34: UAE
A35: GS-800-030 | B35: Cummins QSK23 (800 kVA) | C35: CUMMINS | D35: QSK23-G3 | E35: 2024 | F35: 9524 | G35: UAE
A36: GS-800-031 | B36: Cummins QSK23 (800 kVA) | C36: CUMMINS | D36: QSK23-G3 | E36: 2024 | F36: 2607 | G36: UAE
... A50: GS-1000-038 | B50: Cummins QST30 (1000 kVA) | C50: JCB | D50: QST30-G4 | E50: 2010 | F50: 9321 | G50: UAE
A51: GS-1000-046 | B51: Cummins QST30 (1000 kVA) | C51: JCB | D51: QST30-G4 | E51: 2010 | G51: UAE
A52: GS-1000-047 | B52: Cummins QST30 (1000 kVA) | C52: CUMMINS | D52: QST30-G4 | E52: 2011 | F52: 12274 | G52: UAE → KSA
A53: GS-1000-053 | B53: Cummins QST30 (1000 kVA) | C53: CUMMINS | D53: QST30-G4 | E53: 2011 | F53: 9485 | G53: KSA
A54: GS-1000-055 | B54: Cummins QST30 (1000 kVA) | C54: CUMMINS | D54: QST30-G4 | E54: 2011 | F54: 5637 | G54: KSA
...

Sheet Model comparison
A1: Model | B1: Site-months | C1: In-sample median | D1: Leave-one-site-out: month median | E1: month p90 | F1: bias | G1: site median | H1: site p90 | I1: site worst | J1: 2026 test (fit on 2025): median | K1: bias
A2: kVA classes, no country | B2: 384 | C2: 0.044805863 | D2: 0.059468215 | E2: 0.15858986 | F2: -0.00048864882 | G2: 0.049621222 | H2: 0.14183826 | I2: 0.22278955 | J2: 0.045843399 | K2: 0.0014496571
A3: kVA classes + country | B3: 384 | C3: 0.037563515 | D3: 0.050547231 | E3: 0.15446141 | F3: -0.0031304519 | G3: 0.040221518 | H3: 0.10925855 | I3: 0.17868396 | J3: 0.047873547 | K3: 0.019171514
A4: engine families, no country | B4: 384 | C4: 0.036622995 | D4: 0.063562862 | E4: 0.14520113 | F4: 0.00437869 | G4: 0.044064642 | H4: 0.10199483 | I4: 0.20609514 | J4: 0.04633713 | K4: 0.015420471
A5: engine families + country | B5: 384 | C5: 0.029631142 | D5: 0.048867454 | E5: 0.13831808 | F5: 0.0052182403 | G5: 0.03341879 | H5: 0.10488419 | I5: 0.1834963 | J5: 0.036402856 | K5: 0.021064157
